Workbook

Sheet Sheet
A1: ID | B1: THA ID | C1: İli | D1: İlçesi | E1: Mahallesi | F1: Yüzölçümü (m²) | G1: Nitelik | H1: Onay Durumu | I1: DURUM | J1: Tescil Önceliği | K1: açıklamalarım
A2: 168480 | B2: 16169888 | C2: Mersin | D2: Mezitli | E2: DAVULTEPE | F2: 1090.17 | G2: ESKİ PLANDA MEYDAN YENİ PLANDA KONUT | H2: İHDAS MH | I2: TESCİL EDİLEMEZ | J2: 1.Öncelik - İmar Planı Sahasında | K2: ncz de geometrisi çevrilmemiş MEYDAN VE YOL
A3: 168476 | B3: 16169848 | C3: Mersin | D3: Mezitli | E3: DAVULTEPE | F3: 1006.24 | G3: KAPANAN YOL | H3: İHDAS BELEDİYE | I3: TESCİL EDİLEMEZ | J3: 1.Öncelik - İmar Planı Sahasında
A4: 168477 | B4: 16169987 | C4: Mersin | D4: Mezitli | E4: DAVULTEPE | F4: 906.02 | G4: KAPANAN YOL | H4: İHDAS BELEDİYE | I4: TESCİL EDİLEMEZ | J4: 1.Öncelik - İmar Planı Sahasında
A5: 168484 | B5: 16170110 | C5: Mersin | D5: Mezitli | E5: DAVULTEPE | F5: 669.41 | G5: KISMEN YOL KISMEN PARK (168484_acp yenialan) | H5: İHDAS MH | I5: TESCİL EDİLEBİLİR | J5: 1.Öncelik - İmar Planı Sahasında | K5: 494 parselin parka terkinden ihdas ncz de geometrisi çevrilmemiş
A6: 168592 | B6: 16170014 | C6: Mersin | D6: Mezitli | E6: DAVULTEPE | F6: 665.46 | G6: KAPANAN YOL | H6: İHDAS BELEDİYE | I6: TESCİL EDİLEMEZ | J6: 1.Öncelik - İmar Planı Sahasında
A7: 168602 | B7: 16170015 | C7: Mersin | D7: Mezitli | E7: DAVULTEPE | F7: 705.59 | G7: KAPANAN YOL | H7: İHDAS BELEDİYE | I7: TESCİL EDİLEMEZ | J7: 1.Öncelik - İmar Planı Sahasında
A8: 168481 | B8: 16170025 | C8: Mersin | D8: Mezitli | E8: DAVULTEPE | F8: 535.02 | G8: TERK SONUCU OLUŞMUŞ ALAN NEYE TERK EDİLMİŞ DEĞ BAK | H8: ? | I8: TESCİL EDİLEMEZ | J8: 1.Öncelik - İmar Planı Sahasında | K8: ncz de geometrisi çevrilmemiş YOL VE KONUT
A9: 168486 | B9: 16170165 | C9: Mersin | D9: Mezitli | E9: DAVULTEPE | F9: 479.56 | G9: KAPANAN YOL | H9: İHDAS BELEDİYE | I9: TESCİL EDİLEMEZ | J9: 1.Öncelik - İmar Planı Sahasında
A10: 168593 | B10: 16170414 | C10: Mersin | D10: Mezitli | E10: DAVULTEPE | F10: 411.82 | G10: TERK SONUCU OLUŞMUŞ ALAN NEYE TERK EDİLMİŞ DEĞ BAK (168593/ACP yeni alan) | I10: TESCİL EDİLEBİLİR | J10: 1.Öncelik - İmar Planı Sahasında | K10: 16170414_yeni isimli yeni alan tescil edilebilir. BİR KISMI YOLDA
A11: 168482 | B11: 16170108 | C11: Mersin | D11: Mezitli | E11: DAVULTEPE | F11: 389.01 | G11: KAPANAN YOL | H11: İHDAS BELEDİYE | I11: TESCİL EDİLEMEZ | J11: 1.Öncelik - İmar Planı Sahasında
A12: 168594 | B12: 16169896 | C12: Mersin | D12: Mezitli | E12: DAVULTEPE | F12: 260.69 | G12: KAPANAN YOL | H12: İHDAS BELEDİYE | I12: TESCİL EDİLEMEZ | J12: 1.Öncelik - İmar Planı Sahasında
A13: 168489 | B13: 16170302 | C13: Mersin | D13: Mezitli | E13: DAVULTEPE | F13: 3189.97 | G13: TERK SONUCU OLUŞMUŞ ALAN NEYE TERK EDİLMİŞ DEĞ BAK | H13: ? | I13: ? | J13: 1.Öncelik - İmar Planı Sahasında | K13: geometri yok
A14: 168488 | B14: 16170303 | C14: Mersin | D14: Mezitli | E14: DAVULTEPE | F14: 2345.81 | G14: TERK SONUCU OLUŞMUŞ ALAN NEYE TERK EDİLMİŞ DEĞ BAK | H14: ? | I14: TESCİL EDİLEMEZ | J14: 1.Öncelik - İmar Planı Sahasında | K14: eski 303 parselin uygulamasında ne olarak ayrıldığı bulunamadı
A15: 168491 | B15: 16170398 | C15: Mersin | D15: Mezitli | E15: DAVULTEPE | F15: 576.6 | G15: PARKA TERK SONUCU OLUŞMUŞ ALAN (komşu parsele edit yapıldı) | H15: İHDAS MH | I15: TESCİL EDİLEBİLİR | J15: 1.Öncelik - İmar Planı Sahasında
A16: 168475 | B16: 16170219 | C16: Mersin | D16: Mezitli | E16: DAVULTEPE | F16: 328.11 | G16: TERK SONUCU OLUŞMUŞ ALAN NEYE TERK EDİLMİŞ DEĞ BAK | H16: ? | I16: TESCİL EDİLEMEZ | J16: 1.Öncelik - İmar Planı Sahasında | K16: 384/4 DOĞUSU YOL VE PARK tespit edilemiştir.
A17: 168602 | C17: MERSİN | D17: MEZİTLİ | E17: DAVULTEPE | G17: eski imar planında yol | I17: TESCİL EDİLEMEZ
A18: 168569 | B18: 16965484 | C18: Mersin | D18: Mezitli | E18: FINDIKPINARI | F18: 411.49 | G18: KAPANAN YOL | H18: İHDAS BELEDİYE | I18: TESCİL EDİLEMEZ | J18: 1.Öncelik - İmar Planı Sahasında
A19: 168546 | B19: 16435856 | C19: Mersin | D19: Mezitli | E19: KUYULUK | F19: 6543.86 | G19: TERK SONUCU OLUŞMUŞ ALAN NEYE TERK EDİLMİŞ DEĞ BAK | H19: ? | I19: ? | J19: 1.Öncelik - İmar Planı Sahasında | K19: 2b
A20: 168595 | B20: 16435799 | C20: Mersin | D20: Mezitli | E20: KUYULUK | F20: 2750.7 | G20: ORMAN OLABİLİR | H20: İYT | J20: 1.Öncelik - İmar Planı Sahasında
A21: 168543 | B21: 16435854 | C21: Mersin | D21: Mezitli | E21: KUYULUK | F21: 2520.97 | G21: KISMEN ORMAN OLABİLİR KISMEN 486 PARSELİN DEĞ TERK DEĞ BAK | H21: ? | I21: ? | J21: 1.Öncelik - İmar Planı Sahasında | K21: 486 parselin değ yok bir kısmı geometrisi yok
A22: 168498 | B22: 16436134 | C22: Mersin | D22: Mezitli | E22: KUYULUK | F22: 2173.23 | G22: TERK SONUCU OLUŞMUŞ ALAN NEYE TERK EDİLMİŞ DEĞ BAK 1961 PARSELİN | H22: ? | I22: TESCİL EDİLEMEZ | J22: 1.Öncelik - İmar Planı Sahasında | K22: TESPİT EDİLEMEMİŞTİR.
A23: 168541 | B23: 16435800 | C23: Mersin | D23: Mezitli | E23: KUYULUK | F23: 1898.85 | G23: ORMAN OLABİLİR | H23: ? | I23: ? | J23: 1.Öncelik - İmar Planı Sahasında
A24: 168494 | B24: 16435570 | C24: Mersin | D24: Mezitli | E24: KUYULUK | F24: 1245.16 | G24: PARKA TERK SONUCU OLUŞMUŞ ALAN (168494/acp yeni alan) | H24: İHDAS MH | I24: TESCİL EDİLEBİLİR | J24: 1.Öncelik - İmar Planı Sahasında | K24: 729 parselin parka terk
A25: 168605 | B25: 16435921 | C25: Mersin | D25: Mezitli | E25: KUYULUK | F25: 1159.17 | G25: PARKA TERK SONUCU OLUŞMUŞ ALAN (168605/acp yeni alan konut alanına göre editlendi ) | H25: İHDAS MH | I25: TESCİL EDİLEBİLİR | J25: 1.Öncelik - İmar Planı Sahasında | K25: 608/9 BATISI
A26: 168520 | B26: 16435796 | C26: Mersin | D26: Mezitli | E26: KUYULUK | F26: 1109.7 | G26: TERK SONUCU OLUŞMUŞ ALAN NEYE TERK EDİLMİŞ DEĞ BAK 1918 PARSELİN | H26: ? | I26: TESCİL EDİLEMEZ | J26: 1.Öncelik - İmar Planı Sahasında | K26: 184/1 PARSELİN KUZEYİ YOL VE PARK TESPİT EDİLEMEMİŞTİR.
A27: 168548 | B27: 16435968 | C27: Mersin | D27: Mezitli | E27: KUYULUK | F27: 989.87 | G27: TERK SONUCU OLUŞMUŞ ALAN NEYE TERK EDİLMİŞ DEĞ BAK 1769 PARSELİN | H27: ? | I27: TESCİL EDİLEMEZ | J27: 1.Öncelik - İmar Planı Sahasında
A28: 168550 | B28: 16436103 | C28: Mersin | D28: Mezitli | E28: KUYULUK | F28: 862.95 | G28: 2B BLOĞU VEYA ORMANDA KALIYOR OLABİLİR | H28: ? | I28: ? | J28: 1.Öncelik - İmar Planı Sahasında
A29: 168554 | B29: 16436124 | C29: Mersin | D29: Mezitli | E29: KUYULUK | F29: 831.32 | G29: PARKA TERK SONUCU OLUŞMUŞ ALAN | H29: İHDAS MH | I29: TESCİL EDİLEBİLİR | J29: 1.Öncelik - İmar Planı Sahasında | K29: 244/2 KUZEY DOĞUSU
A30: 168505 | B30: 16435794 | C30: Mersin | D30: Mezitli | E30: KUYULUK | F30: 773.47 | G30: 1915 DEĞİŞİKLİĞİ İNCELE PARK VEYA YOL TERK İŞLEMİ YOK ESKİ PLAN DA KONUT | H30: ? | I30: TESCİL EDİLEMEZ | J30: 1.Öncelik - İmar Planı Sahasında
A31: 168590 | B31: 16436109 | C31: Mersin | D31: Mezitli | E31: KUYULUK | F31: 743.43 | G31: PARKA TERK SONUCU OLUŞMUŞ ALAN (168590/acp yeni alan) | H31: İHDAS MH | I31: TESCİL EDİLEBİLİR | J31: 1.Öncelik - İmar Planı Sahasında | K31: 256/1 BATISI
A32: 168606 | B32: 16436048 | C32: Mersin | D32: Mezitli | E32: KUYULUK | F32: 618.48 | G32: PARKA TERK SONUCU OLUŞMUŞ ALAN (168606/acp yeni alan) | H32: İHDAS MH | I32: TESCİL EDİLEBİLİR | J32: 1.Öncelik - İmar Planı Sahasında | K32: 67/10 GÜNEYİ
A33: 168552 | B33: 16436103 | C33: Mersin | D33: Mezitli | E33: KUYULUK | F33: 545.36 | G33: TERK SONUCU OLUŞMUŞ ALAN NEYE TERK EDİLMİŞ DEĞ BAK 1923-1925PARSELİN | I33: TESCİL EDİLEMEZ | J33: 1.Öncelik - İmar Planı Sahasında | K33: TESPİT EDİLEMEMİŞTİR.
A34: 168601 | B34: 16436042 | C34: Mersin | D34: Mezitli | E34: KUYULUK | F34: 464.73 | G34: PARKA TERK SONUCU OLUŞMUŞ ALAN (168601/acp yeni alan) | H34: İHDAS MH | I34: TESCİL EDİLEBİLİR | J34: 1.Öncelik - İmar Planı Sahasında | K34: 1000/1 GÜNEYİ
A35: 168597 | B35: 16436036 | C35: Mersin | D35: Mezitli | E35: KUYULUK | F35: 500.87 | G35: PARKA TERK SONUCU OLUŞMUŞ ALAN (168597/acp yeni alan) | H35: İHDAS MH | I35: TESCİL EDİLEBİLİR | J35: 1.Öncelik - İmar Planı Sahasında | K35: 674/9 GÜNEYİ
A36: 168607 | B36: 16436034 | C36: Mersin | D36: Mezitli | E36: KUYULUK | F36: 396.27 | G36: PARKA TERK SONUCU OLUŞMUŞ ALAN | H36: İHDAS MH | I36: TESCİL EDİLEBİLİR | J36: 1.Öncelik - İmar Planı Sahasında | K36: 11/9 GÜNEYİ
A37: 168540 | B37: 16435841 | C37: Mersin | D37: Mezitli | E37: KUYULUK | F37: 340.06 | G37: ORMAN OLABİLİR | H37: ? | I37: ? | J37: 1.Öncelik - İmar Planı Sahasında
A38: 168603 | B38: 16436065 | C38: Mersin | D38: Mezitli | E38: KUYULUK | F38: 356.25 | G38: PARKA TERK SONUCU OLUŞMUŞ ALAN (168603/acp yeni alan) | H38: İHDAS MH | I38: TESCİL EDİLEBİLİR | J38: 1.Öncelik - İmar Planı Sahasında | K38: 321/1 GÜNEYİ
A39: 168608 | B39: 16436116 | C39: Mersin | D39: Mezitli | E39: KUYULUK | F39: 405.62 | G39: TERK SONUCU OLUŞMUŞ ALAN NEYE TERK EDİLMİŞ DEĞ BAK | H39: ? | I39: ? | J39: 1.Öncelik - İmar Planı Sahasında | K39: TESPİT EDİLEMEMİŞTİR.
A40: 168548 | C40: MERSİN | D40: MEZİTLİ | E40: KUYULUK | G40: 1771-1772-1773 parseller var | I40: TESCİL EDİLEMEZ
...

Sheet Sayfa1
A1: 168484 | B1: 16170110 | C1: Mersin | D1: Mezitli | E1: DAVULTEPE | F1: 669.41 | G1: KISMEN YOL KISMEN PARK | H1: İHDAS MH | I1: TESCİL EDİLEBİLİR | L1: 168484 | M1: MERSİN | N1: MEZİTLİ | O1: DAVULTEPE | Q1: =L1=A1 -> TRUE
A2: 168491 | B2: 16170398 | C2: Mersin | D2: Mezitli | E2: DAVULTEPE | F2: 576.6 | G2: PARKA TERK SONUCU OLUŞMUŞ ALAN | H2: İHDAS MH | I2: TESCİL EDİLEBİLİR | L2: 168491 | M2: MERSİN | N2: MEZİTLİ | O2: DAVULTEPE | Q2: =L2=A2 -> TRUE
A3: 168593 | B3: 16170414 | C3: Mersin | D3: Mezitli | E3: DAVULTEPE | F3: 411.82 | G3: TERK SONUCU OLUŞMUŞ ALAN NEYE TERK EDİLMİŞ DEĞ BAK | H3: ? | I3: TESCİL EDİLEBİLİR | L3: 168593 | M3: MERSİN | N3: MEZİTLİ | O3: DAVULTEPE | Q3: =L3=A3 -> TRUE
Q4: =Sheet!A17=A4 -> FALSE
A5: 168494 | B5: 16435570 | C5: Mersin | D5: Mezitli | E5: KUYULUK | F5: 1245.16 | G5: PARKA TERK SONUCU OLUŞMUŞ ALAN | H5: İHDAS MH | I5: TESCİL EDİLEBİLİR | L5: 168494 | M5: MERSİN | N5: MEZİTLİ | O5: KUYULUK | Q5: =L5=A5 -> TRUE
Q6: =Sheet!A40=A6 -> FALSE
Q7: =Sheet!A41=A7 -> FALSE
Q8: =Sheet!A42=A8 -> FALSE
A9: 168554 | B9: 16436124 | C9: Mersin | D9: Mezitli | E9: KUYULUK | F9: 831.32 | G9: PARKA TERK SONUCU OLUŞMUŞ ALAN | H9: İHDAS MH | I9: TESCİL EDİLEBİLİR | L9: 168554 | M9: MERSİN | N9: MEZİTLİ | O9: KUYULUK | Q9: =L9=A9 -> TRUE
A10: 168590 | B10: 16436109 | C10: Mersin | D10: Mezitli | E10: KUYULUK | F10: 743.43 | G10: PARKA TERK SONUCU OLUŞMUŞ ALAN | H10: İHDAS MH | I10: TESCİL EDİLEBİLİR | L10: 168590 | M10: MERSİN | N10: MEZİTLİ | O10: KUYULUK | Q10: =L10=A10 -> TRUE
A11: 168597 | B11: 16436036 | C11: Mersin | D11: Mezitli | E11: KUYULUK | F11: 500.87 | G11: PARKA TERK SONUCU OLUŞMUŞ ALAN | H11: İHDAS MH | I11: TESCİL EDİLEBİLİR | L11: 168597 | M11: MERSİN | N11: MEZİTLİ | O11: KUYULUK | Q11: =L11=A11 -> TRUE
A12: 168601 | B12: 16436042 | C12: Mersin | D12: Mezitli | E12: KUYULUK | F12: 464.73 | G12: PARKA TERK SONUCU OLUŞMUŞ ALAN | H12: İHDAS MH | I12: TESCİL EDİLEBİLİR | L12: 168601 | M12: MERSİN | N12: MEZİTLİ | O12: KUYULUK | Q12: =L12=A12 -> TRUE
A13: 168603 | B13: 16436065 | C13: Mersin | D13: Mezitli | E13: KUYULUK | F13: 356.25 | G13: PARKA TERK SONUCU OLUŞMUŞ ALAN | H13: İHDAS MH | I13: TESCİL EDİLEBİLİR | L13: 168603 | M13: MERSİN | N13: MEZİTLİ | O13: KUYULUK | Q13: =L13=A13 -> TRUE
A14: 168605 | B14: 16435921 | C14: Mersin | D14: Mezitli | E14: KUYULUK | F14: 1159.17 | G14: PARKA TERK SONUCU OLUŞMUŞ ALAN | H14: İHDAS MH | I14: TESCİL EDİLEBİLİR | L14: 168605 | M14: MERSİN | N14: MEZİTLİ | O14: KUYULUK | Q14: =L14=A14 -> TRUE
A15: 168606 | B15: 16436048 | C15: Mersin | D15: Mezitli | E15: KUYULUK | F15: 618.48 | G15: PARKA TERK SONUCU OLUŞMUŞ ALAN | H15: İHDAS MH | I15: TESCİL EDİLEBİLİR | L15: 168606 | M15: MERSİN | N15: MEZİTLİ | O15: KUYULUK | Q15: =L15=A15 -> TRUE
A16: 168607 | B16: 16436034 | C16: Mersin | D16: Mezitli | E16: KUYULUK | F16: 396.27 | G16: PARKA TERK SONUCU OLUŞMUŞ ALAN | H16: İHDAS MH | I16: TESCİL EDİLEBİLİR | L16: 168607 | M16: MERSİN | N16: MEZİTLİ | O16: KUYULUK | Q16: =L16=A16 -> TRUE
A17: 168571 | B17: 19383837 | C17: Mersin | D17: Mezitli | E17: MEZİTLİ | F17: 1650.4 | G17: PARKA TERK SONUCU OLUŞMUŞ ALAN | H17: İHDAS MH | I17: TESCİL EDİLEBİLİR | L17: 168571 | M17: MERSİN | N17: MEZİTLİ | O17: MEZİTLİ | Q17: =L17=A17 -> TRUE
A18: 168576 | B18: 19383839 | C18: Mersin | D18: Mezitli | E18: MEZİTLİ | F18: 2313.81 | G18: PARKA TERK SONUCU OLUŞMUŞ ALAN | H18: İHDAS MH | I18: TESCİL EDİLEBİLİR | L18: 168576 | M18: MERSİN | N18: MEZİTLİ | O18: MEZİTLİ | Q18: =L18=A18 -> TRUE
A19: 168591 | B19: 19383840 | C19: Mersin | D19: Mezitli | E19: MEZİTLİ | F19: 1693.36 | G19: PARKA TERK SONUCU OLUŞMUŞ ALAN | H19: İHDAS MH | I19: TESCİL EDİLEBİLİR | L19: 168591 | M19: MERSİN | N19: MEZİTLİ | O19: MEZİTLİ | Q19: =L19=A19 -> TRUE
Q20: =Sheet!A169=A20 -> FALSE
Q21: =Sheet!A170=A21 -> FALSE
Q22: =Sheet!A171=A22 -> FALSE
Q23: =Sheet!A172=A23 -> FALSE
Q24: =Sheet!A173=A24 -> FALSE
Q25: =Sheet!A174=A25 -> FALSE
Q26: =Sheet!A175=A26 -> FALSE
